Internal Server Error: /api/stores/register/
"POST /api/stores/register/ HTTP/1.1" 500 60
Internal Server Error: /api/stores/register/
"POST /api/stores/register/ HTTP/1.1" 500 60
Internal Server Error: /api/stores/register/
"POST /api/stores/register/ HTTP/1.1" 500 60
Internal Server Error: /api/stores/register/
"POST /api/stores/register/ HTTP/1.1" 500 60
Internal Server Error: /api/stores/register/
"POST /api/stores/register/ HTTP/1.1" 500 60
Internal Server Error: /api/stores/register/
"POST /api/stores/register/ HTTP/1.1" 500 60
Internal Server Error: /api/stores/register/
"POST /api/stores/register/ HTTP/1.1" 500 60
Internal Server Error: /api/stores/register/
"POST /api/stores/register/ HTTP/1.1" 500 60
Internal Server Error: /api/stores/register/
"POST /api/stores/register/ HTTP/1.1" 500 60
Internal Server Error: /api/stores/register/
"POST /api/stores/register/ HTTP/1.1" 500 60
Internal Server Error: /api/stores/register/
"POST /api/stores/register/ HTTP/1.1" 500 60
Internal Server Error: /api/stores/register/
"POST /api/stores/register/ HTTP/1.1" 500 60
Internal Server Error: /api/stores/register/
"POST /api/stores/register/ HTTP/1.1" 500 60
Internal Server Error: /api/stores/register/
"POST /api/stores/register/ HTTP/1.1" 500 60
Internal Server Error: /api/stores/register/
"POST /api/stores/register/ HTTP/1.1" 500 60
Internal Server Error: /api/stores/register/
"POST /api/stores/register/ HTTP/1.1" 500 60
Internal Server Error: /api/analytics/statistics/1/
Traceback (most recent call last):
  File "C:\Users\HP NEW\Downloads\enlist\env\Lib\site-packages\django\db\models\query.py", line 948, in get_or_create
    return self.get(**kwargs), False
           ^^^^^^^^^^^^^^^^^^
  File "C:\Users\HP NEW\Downloads\enlist\env\Lib\site-packages\django\db\models\query.py", line 649, in get
    raise self.model.DoesNotExist(
analytics.models.StoreVisitor.DoesNotExist: StoreVisitor matching query does not exist.

During handling of the above exception, another exception occurred:

Traceback (most recent call last):
  File "C:\Users\HP NEW\Downloads\enlist\env\Lib\site-packages\django\core\handlers\exception.py", line 55, in inner
    response = get_response(request)
               ^^^^^^^^^^^^^^^^^^^^^
  File "C:\Users\HP NEW\Downloads\enlist\env\Lib\site-packages\django\core\handlers\base.py", line 185, in _get_response
    response = middleware_method(
               ^^^^^^^^^^^^^^^^^^
  File "C:\Users\HP NEW\Downloads\enlist\analytics\middleware.py", line 12, in process_view
    StoreVisitor.objects.update_or_create(
  File "C:\Users\HP NEW\Downloads\enlist\env\Lib\site-packages\django\db\models\manager.py", line 87, in manager_method
    return getattr(self.get_queryset(), name)(*args, **kwargs)
           ^^^^^^^^^^^^^^^^^^^^^^^^^^^^^^^^^^^^^^^^^^^^^^^^^^^
  File "C:\Users\HP NEW\Downloads\enlist\env\Lib\site-packages\django\db\models\query.py", line 986, in update_or_create
    obj, created = self.select_for_update().get_or_create(
                   ^^^^^^^^^^^^^^^^^^^^^^^^^^^^^^^^^^^^^^^
  File "C:\Users\HP NEW\Downloads\enlist\env\Lib\site-packages\django\db\models\query.py", line 955, in get_or_create
    return self.create(**params), True
           ^^^^^^^^^^^^^^^^^^^^^
  File "C:\Users\HP NEW\Downloads\enlist\env\Lib\site-packages\django\db\models\query.py", line 679, in create
    obj.save(force_insert=True, using=self.db)
  File "C:\Users\HP NEW\Downloads\enlist\env\Lib\site-packages\django\db\models\base.py", line 822, in save
    self.save_base(
  File "C:\Users\HP NEW\Downloads\enlist\env\Lib\site-packages\django\db\models\base.py", line 909, in save_base
    updated = self._save_table(
              ^^^^^^^^^^^^^^^^^
  File "C:\Users\HP NEW\Downloads\enlist\env\Lib\site-packages\django\db\models\base.py", line 1071, in _save_table
    results = self._do_insert(
              ^^^^^^^^^^^^^^^^
  File "C:\Users\HP NEW\Downloads\enlist\env\Lib\site-packages\django\db\models\base.py", line 1112, in _do_insert
    return manager._insert(
           ^^^^^^^^^^^^^^^^
  File "C:\Users\HP NEW\Downloads\enlist\env\Lib\site-packages\django\db\models\manager.py", line 87, in manager_method
    return getattr(self.get_queryset(), name)(*args, **kwargs)
           ^^^^^^^^^^^^^^^^^^^^^^^^^^^^^^^^^^^^^^^^^^^^^^^^^^^
  File "C:\Users\HP NEW\Downloads\enlist\env\Lib\site-packages\django\db\models\query.py", line 1847, in _insert
    return query.get_compiler(using=using).execute_sql(returning_fields)
           ^^^^^^^^^^^^^^^^^^^^^^^^^^^^^^^^^^^^^^^^^^^^^^^^^^^^^^^^^^^^^
  File "C:\Users\HP NEW\Downloads\enlist\env\Lib\site-packages\django\db\models\sql\compiler.py", line 1822, in execute_sql
    for sql, params in self.as_sql():
                       ^^^^^^^^^^^^^
  File "C:\Users\HP NEW\Downloads\enlist\env\Lib\site-packages\django\db\models\sql\compiler.py", line 1747, in as_sql
    self.prepare_value(field, self.pre_save_val(field, obj))
  File "C:\Users\HP NEW\Downloads\enlist\env\Lib\site-packages\django\db\models\sql\compiler.py", line 1672, in prepare_value
    raise ValueError(
ValueError: Failed to insert expression "Col(analytics_storevisitor, analytics.StoreVisitor.visitor_count) + Value(1)" on analytics.StoreVisitor.visitor_count. F() expressions can only be used to update, not to insert.
"GET /api/analytics/statistics/1/ HTTP/1.1" 500 143998
Internal Server Error: /api/analytics/statistics/1/
Traceback (most recent call last):
  File "C:\Users\HP NEW\Downloads\enlist\env\Lib\site-packages\django\db\models\query.py", line 948, in get_or_create
    return self.get(**kwargs), False
           ^^^^^^^^^^^^^^^^^^
  File "C:\Users\HP NEW\Downloads\enlist\env\Lib\site-packages\django\db\models\query.py", line 649, in get
    raise self.model.DoesNotExist(
analytics.models.StoreVisitor.DoesNotExist: StoreVisitor matching query does not exist.

During handling of the above exception, another exception occurred:

Traceback (most recent call last):
  File "C:\Users\HP NEW\Downloads\enlist\env\Lib\site-packages\django\core\handlers\exception.py", line 55, in inner
    response = get_response(request)
               ^^^^^^^^^^^^^^^^^^^^^
  File "C:\Users\HP NEW\Downloads\enlist\env\Lib\site-packages\django\core\handlers\base.py", line 185, in _get_response
    response = middleware_method(
               ^^^^^^^^^^^^^^^^^^
  File "C:\Users\HP NEW\Downloads\enlist\analytics\middleware.py", line 12, in process_view
    StoreVisitor.objects.update_or_create(
  File "C:\Users\HP NEW\Downloads\enlist\env\Lib\site-packages\django\db\models\manager.py", line 87, in manager_method
    return getattr(self.get_queryset(), name)(*args, **kwargs)
           ^^^^^^^^^^^^^^^^^^^^^^^^^^^^^^^^^^^^^^^^^^^^^^^^^^^
  File "C:\Users\HP NEW\Downloads\enlist\env\Lib\site-packages\django\db\models\query.py", line 986, in update_or_create
    obj, created = self.select_for_update().get_or_create(
                   ^^^^^^^^^^^^^^^^^^^^^^^^^^^^^^^^^^^^^^^
  File "C:\Users\HP NEW\Downloads\enlist\env\Lib\site-packages\django\db\models\query.py", line 955, in get_or_create
    return self.create(**params), True
           ^^^^^^^^^^^^^^^^^^^^^
  File "C:\Users\HP NEW\Downloads\enlist\env\Lib\site-packages\django\db\models\query.py", line 679, in create
    obj.save(force_insert=True, using=self.db)
  File "C:\Users\HP NEW\Downloads\enlist\env\Lib\site-packages\django\db\models\base.py", line 822, in save
    self.save_base(
  File "C:\Users\HP NEW\Downloads\enlist\env\Lib\site-packages\django\db\models\base.py", line 909, in save_base
    updated = self._save_table(
              ^^^^^^^^^^^^^^^^^
  File "C:\Users\HP NEW\Downloads\enlist\env\Lib\site-packages\django\db\models\base.py", line 1071, in _save_table
    results = self._do_insert(
              ^^^^^^^^^^^^^^^^
  File "C:\Users\HP NEW\Downloads\enlist\env\Lib\site-packages\django\db\models\base.py", line 1112, in _do_insert
    return manager._insert(
           ^^^^^^^^^^^^^^^^
  File "C:\Users\HP NEW\Downloads\enlist\env\Lib\site-packages\django\db\models\manager.py", line 87, in manager_method
    return getattr(self.get_queryset(), name)(*args, **kwargs)
           ^^^^^^^^^^^^^^^^^^^^^^^^^^^^^^^^^^^^^^^^^^^^^^^^^^^
  File "C:\Users\HP NEW\Downloads\enlist\env\Lib\site-packages\django\db\models\query.py", line 1847, in _insert
    return query.get_compiler(using=using).execute_sql(returning_fields)
           ^^^^^^^^^^^^^^^^^^^^^^^^^^^^^^^^^^^^^^^^^^^^^^^^^^^^^^^^^^^^^
  File "C:\Users\HP NEW\Downloads\enlist\env\Lib\site-packages\django\db\models\sql\compiler.py", line 1822, in execute_sql
    for sql, params in self.as_sql():
                       ^^^^^^^^^^^^^
  File "C:\Users\HP NEW\Downloads\enlist\env\Lib\site-packages\django\db\models\sql\compiler.py", line 1747, in as_sql
    self.prepare_value(field, self.pre_save_val(field, obj))
  File "C:\Users\HP NEW\Downloads\enlist\env\Lib\site-packages\django\db\models\sql\compiler.py", line 1672, in prepare_value
    raise ValueError(
ValueError: Failed to insert expression "Col(analytics_storevisitor, analytics.StoreVisitor.visitor_count) + Value(1)" on analytics.StoreVisitor.visitor_count. F() expressions can only be used to update, not to insert.
"GET /api/analytics/statistics/1/ HTTP/1.1" 500 143998
Internal Server Error: /api/analytics/statistics/1/
Traceback (most recent call last):
  File "C:\Users\HP NEW\Downloads\enlist\env\Lib\site-packages\django\db\models\query.py", line 948, in get_or_create
    return self.get(**kwargs), False
           ^^^^^^^^^^^^^^^^^^
  File "C:\Users\HP NEW\Downloads\enlist\env\Lib\site-packages\django\db\models\query.py", line 649, in get
    raise self.model.DoesNotExist(
analytics.models.StoreVisitor.DoesNotExist: StoreVisitor matching query does not exist.

During handling of the above exception, another exception occurred:

Traceback (most recent call last):
  File "C:\Users\HP NEW\Downloads\enlist\env\Lib\site-packages\django\core\handlers\exception.py", line 55, in inner
    response = get_response(request)
               ^^^^^^^^^^^^^^^^^^^^^
  File "C:\Users\HP NEW\Downloads\enlist\env\Lib\site-packages\django\core\handlers\base.py", line 185, in _get_response
    response = middleware_method(
               ^^^^^^^^^^^^^^^^^^
  File "C:\Users\HP NEW\Downloads\enlist\analytics\middleware.py", line 12, in process_view
    StoreVisitor.objects.update_or_create(
  File "C:\Users\HP NEW\Downloads\enlist\env\Lib\site-packages\django\db\models\manager.py", line 87, in manager_method
    return getattr(self.get_queryset(), name)(*args, **kwargs)
           ^^^^^^^^^^^^^^^^^^^^^^^^^^^^^^^^^^^^^^^^^^^^^^^^^^^
  File "C:\Users\HP NEW\Downloads\enlist\env\Lib\site-packages\django\db\models\query.py", line 986, in update_or_create
    obj, created = self.select_for_update().get_or_create(
                   ^^^^^^^^^^^^^^^^^^^^^^^^^^^^^^^^^^^^^^^
  File "C:\Users\HP NEW\Downloads\enlist\env\Lib\site-packages\django\db\models\query.py", line 955, in get_or_create
    return self.create(**params), True
           ^^^^^^^^^^^^^^^^^^^^^
  File "C:\Users\HP NEW\Downloads\enlist\env\Lib\site-packages\django\db\models\query.py", line 679, in create
    obj.save(force_insert=True, using=self.db)
  File "C:\Users\HP NEW\Downloads\enlist\env\Lib\site-packages\django\db\models\base.py", line 822, in save
    self.save_base(
  File "C:\Users\HP NEW\Downloads\enlist\env\Lib\site-packages\django\db\models\base.py", line 909, in save_base
    updated = self._save_table(
              ^^^^^^^^^^^^^^^^^
  File "C:\Users\HP NEW\Downloads\enlist\env\Lib\site-packages\django\db\models\base.py", line 1071, in _save_table
    results = self._do_insert(
              ^^^^^^^^^^^^^^^^
  File "C:\Users\HP NEW\Downloads\enlist\env\Lib\site-packages\django\db\models\base.py", line 1112, in _do_insert
    return manager._insert(
           ^^^^^^^^^^^^^^^^
  File "C:\Users\HP NEW\Downloads\enlist\env\Lib\site-packages\django\db\models\manager.py", line 87, in manager_method
    return getattr(self.get_queryset(), name)(*args, **kwargs)
           ^^^^^^^^^^^^^^^^^^^^^^^^^^^^^^^^^^^^^^^^^^^^^^^^^^^
  File "C:\Users\HP NEW\Downloads\enlist\env\Lib\site-packages\django\db\models\query.py", line 1847, in _insert
    return query.get_compiler(using=using).execute_sql(returning_fields)
           ^^^^^^^^^^^^^^^^^^^^^^^^^^^^^^^^^^^^^^^^^^^^^^^^^^^^^^^^^^^^^
  File "C:\Users\HP NEW\Downloads\enlist\env\Lib\site-packages\django\db\models\sql\compiler.py", line 1822, in execute_sql
    for sql, params in self.as_sql():
                       ^^^^^^^^^^^^^
  File "C:\Users\HP NEW\Downloads\enlist\env\Lib\site-packages\django\db\models\sql\compiler.py", line 1747, in as_sql
    self.prepare_value(field, self.pre_save_val(field, obj))
  File "C:\Users\HP NEW\Downloads\enlist\env\Lib\site-packages\django\db\models\sql\compiler.py", line 1672, in prepare_value
    raise ValueError(
ValueError: Failed to insert expression "Col(analytics_storevisitor, analytics.StoreVisitor.visitor_count) + Value(1)" on analytics.StoreVisitor.visitor_count. F() expressions can only be used to update, not to insert.
"GET /api/analytics/statistics/1/ HTTP/1.1" 500 143998
Internal Server Error: /api/analytics/statistics/1/
Traceback (most recent call last):
  File "C:\Users\HP NEW\Downloads\enlist\analytics\middleware.py", line 17, in process_view
    store_visitor = StoreVisitor.objects.get(store_id=store_id, visit_date=today)
                    ^^^^^^^^^^^^^^^^^^^^^^^^^^^^^^^^^^^^^^^^^^^^^^^^^^^^^^^^^^^^^
  File "C:\Users\HP NEW\Downloads\enlist\env\Lib\site-packages\django\db\models\manager.py", line 87, in manager_method
    return getattr(self.get_queryset(), name)(*args, **kwargs)
           ^^^^^^^^^^^^^^^^^^^^^^^^^^^^^^^^^^^^^^^^^^^^^^^^^^^
  File "C:\Users\HP NEW\Downloads\enlist\env\Lib\site-packages\django\db\models\query.py", line 649, in get
    raise self.model.DoesNotExist(
analytics.models.StoreVisitor.DoesNotExist: StoreVisitor matching query does not exist.

During handling of the above exception, another exception occurred:

Traceback (most recent call last):
  File "C:\Users\HP NEW\Downloads\enlist\env\Lib\site-packages\django\db\backends\utils.py", line 105, in _execute
    return self.cursor.execute(sql, params)
           ^^^^^^^^^^^^^^^^^^^^^^^^^^^^^^^^
psycopg2.errors.ForeignKeyViolation: insert or update on table "analytics_storevisitor" violates foreign key constraint "analytics_storevisit_store_id_bb8f47ea_fk_stores_st"
DETAIL:  Key (store_id)=(1) is not present in table "stores_storeuserprofile".


The above exception was the direct cause of the following exception:

Traceback (most recent call last):
  File "C:\Users\HP NEW\Downloads\enlist\env\Lib\site-packages\django\core\handlers\exception.py", line 55, in inner
    response = get_response(request)
               ^^^^^^^^^^^^^^^^^^^^^
  File "C:\Users\HP NEW\Downloads\enlist\env\Lib\site-packages\django\core\handlers\base.py", line 185, in _get_response
    response = middleware_method(
               ^^^^^^^^^^^^^^^^^^
  File "C:\Users\HP NEW\Downloads\enlist\analytics\middleware.py", line 22, in process_view
    StoreVisitor.objects.create(
  File "C:\Users\HP NEW\Downloads\enlist\env\Lib\site-packages\django\db\models\manager.py", line 87, in manager_method
    return getattr(self.get_queryset(), name)(*args, **kwargs)
           ^^^^^^^^^^^^^^^^^^^^^^^^^^^^^^^^^^^^^^^^^^^^^^^^^^^
  File "C:\Users\HP NEW\Downloads\enlist\env\Lib\site-packages\django\db\models\query.py", line 679, in create
    obj.save(force_insert=True, using=self.db)
  File "C:\Users\HP NEW\Downloads\enlist\env\Lib\site-packages\django\db\models\base.py", line 822, in save
    self.save_base(
  File "C:\Users\HP NEW\Downloads\enlist\env\Lib\site-packages\django\db\models\base.py", line 909, in save_base
    updated = self._save_table(
              ^^^^^^^^^^^^^^^^^
  File "C:\Users\HP NEW\Downloads\enlist\env\Lib\site-packages\django\db\models\base.py", line 1071, in _save_table
    results = self._do_insert(
              ^^^^^^^^^^^^^^^^
  File "C:\Users\HP NEW\Downloads\enlist\env\Lib\site-packages\django\db\models\base.py", line 1112, in _do_insert
    return manager._insert(
           ^^^^^^^^^^^^^^^^
  File "C:\Users\HP NEW\Downloads\enlist\env\Lib\site-packages\django\db\models\manager.py", line 87, in manager_method
    return getattr(self.get_queryset(), name)(*args, **kwargs)
           ^^^^^^^^^^^^^^^^^^^^^^^^^^^^^^^^^^^^^^^^^^^^^^^^^^^
  File "C:\Users\HP NEW\Downloads\enlist\env\Lib\site-packages\django\db\models\query.py", line 1847, in _insert
    return query.get_compiler(using=using).execute_sql(returning_fields)
           ^^^^^^^^^^^^^^^^^^^^^^^^^^^^^^^^^^^^^^^^^^^^^^^^^^^^^^^^^^^^^
  File "C:\Users\HP NEW\Downloads\enlist\env\Lib\site-packages\django\db\models\sql\compiler.py", line 1823, in execute_sql
    cursor.execute(sql, params)
  File "C:\Users\HP NEW\Downloads\enlist\env\Lib\site-packages\django\db\backends\utils.py", line 122, in execute
    return super().execute(sql, params)
           ^^^^^^^^^^^^^^^^^^^^^^^^^^^^
  File "C:\Users\HP NEW\Downloads\enlist\env\Lib\site-packages\django\db\backends\utils.py", line 79, in execute
    return self._execute_with_wrappers(
           ^^^^^^^^^^^^^^^^^^^^^^^^^^^^
  File "C:\Users\HP NEW\Downloads\enlist\env\Lib\site-packages\django\db\backends\utils.py", line 92, in _execute_with_wrappers
    return executor(sql, params, many, context)
           ^^^^^^^^^^^^^^^^^^^^^^^^^^^^^^^^^^^^
  File "C:\Users\HP NEW\Downloads\enlist\env\Lib\site-packages\django\db\backends\utils.py", line 100, in _execute
    with self.db.wrap_database_errors:
  File "C:\Users\HP NEW\Downloads\enlist\env\Lib\site-packages\django\db\utils.py", line 91, in __exit__
    raise dj_exc_value.with_traceback(traceback) from exc_value
  File "C:\Users\HP NEW\Downloads\enlist\env\Lib\site-packages\django\db\backends\utils.py", line 105, in _execute
    return self.cursor.execute(sql, params)
           ^^^^^^^^^^^^^^^^^^^^^^^^^^^^^^^^
django.db.utils.IntegrityError: insert or update on table "analytics_storevisitor" violates foreign key constraint "analytics_storevisit_store_id_bb8f47ea_fk_stores_st"
DETAIL:  Key (store_id)=(1) is not present in table "stores_storeuserprofile".

"GET /api/analytics/statistics/1/ HTTP/1.1" 500 165463
Internal Server Error: /api/analytics/statistics/1/
Traceback (most recent call last):
  File "C:\Users\HP NEW\Downloads\enlist\analytics\middleware.py", line 17, in process_view
    store_visitor = StoreVisitor.objects.get(store_id=store_id, visit_date=today)
                    ^^^^^^^^^^^^^^^^^^^^^^^^^^^^^^^^^^^^^^^^^^^^^^^^^^^^^^^^^^^^^
  File "C:\Users\HP NEW\Downloads\enlist\env\Lib\site-packages\django\db\models\manager.py", line 87, in manager_method
    return getattr(self.get_queryset(), name)(*args, **kwargs)
           ^^^^^^^^^^^^^^^^^^^^^^^^^^^^^^^^^^^^^^^^^^^^^^^^^^^
  File "C:\Users\HP NEW\Downloads\enlist\env\Lib\site-packages\django\db\models\query.py", line 649, in get
    raise self.model.DoesNotExist(
analytics.models.StoreVisitor.DoesNotExist: StoreVisitor matching query does not exist.

During handling of the above exception, another exception occurred:

Traceback (most recent call last):
  File "C:\Users\HP NEW\Downloads\enlist\env\Lib\site-packages\django\db\backends\utils.py", line 105, in _execute
    return self.cursor.execute(sql, params)
           ^^^^^^^^^^^^^^^^^^^^^^^^^^^^^^^^
psycopg2.errors.ForeignKeyViolation: insert or update on table "analytics_storevisitor" violates foreign key constraint "analytics_storevisit_store_id_bb8f47ea_fk_stores_st"
DETAIL:  Key (store_id)=(1) is not present in table "stores_storeuserprofile".


The above exception was the direct cause of the following exception:

Traceback (most recent call last):
  File "C:\Users\HP NEW\Downloads\enlist\env\Lib\site-packages\django\core\handlers\exception.py", line 55, in inner
    response = get_response(request)
               ^^^^^^^^^^^^^^^^^^^^^
  File "C:\Users\HP NEW\Downloads\enlist\env\Lib\site-packages\django\core\handlers\base.py", line 185, in _get_response
    response = middleware_method(
               ^^^^^^^^^^^^^^^^^^
  File "C:\Users\HP NEW\Downloads\enlist\analytics\middleware.py", line 22, in process_view
    StoreVisitor.objects.create(
  File "C:\Users\HP NEW\Downloads\enlist\env\Lib\site-packages\django\db\models\manager.py", line 87, in manager_method
    return getattr(self.get_queryset(), name)(*args, **kwargs)
           ^^^^^^^^^^^^^^^^^^^^^^^^^^^^^^^^^^^^^^^^^^^^^^^^^^^
  File "C:\Users\HP NEW\Downloads\enlist\env\Lib\site-packages\django\db\models\query.py", line 679, in create
    obj.save(force_insert=True, using=self.db)
  File "C:\Users\HP NEW\Downloads\enlist\env\Lib\site-packages\django\db\models\base.py", line 822, in save
    self.save_base(
  File "C:\Users\HP NEW\Downloads\enlist\env\Lib\site-packages\django\db\models\base.py", line 909, in save_base
    updated = self._save_table(
              ^^^^^^^^^^^^^^^^^
  File "C:\Users\HP NEW\Downloads\enlist\env\Lib\site-packages\django\db\models\base.py", line 1071, in _save_table
    results = self._do_insert(
              ^^^^^^^^^^^^^^^^
  File "C:\Users\HP NEW\Downloads\enlist\env\Lib\site-packages\django\db\models\base.py", line 1112, in _do_insert
    return manager._insert(
           ^^^^^^^^^^^^^^^^
  File "C:\Users\HP NEW\Downloads\enlist\env\Lib\site-packages\django\db\models\manager.py", line 87, in manager_method
    return getattr(self.get_queryset(), name)(*args, **kwargs)
           ^^^^^^^^^^^^^^^^^^^^^^^^^^^^^^^^^^^^^^^^^^^^^^^^^^^
  File "C:\Users\HP NEW\Downloads\enlist\env\Lib\site-packages\django\db\models\query.py", line 1847, in _insert
    return query.get_compiler(using=using).execute_sql(returning_fields)
           ^^^^^^^^^^^^^^^^^^^^^^^^^^^^^^^^^^^^^^^^^^^^^^^^^^^^^^^^^^^^^
  File "C:\Users\HP NEW\Downloads\enlist\env\Lib\site-packages\django\db\models\sql\compiler.py", line 1823, in execute_sql
    cursor.execute(sql, params)
  File "C:\Users\HP NEW\Downloads\enlist\env\Lib\site-packages\django\db\backends\utils.py", line 122, in execute
    return super().execute(sql, params)
           ^^^^^^^^^^^^^^^^^^^^^^^^^^^^
  File "C:\Users\HP NEW\Downloads\enlist\env\Lib\site-packages\django\db\backends\utils.py", line 79, in execute
    return self._execute_with_wrappers(
           ^^^^^^^^^^^^^^^^^^^^^^^^^^^^
  File "C:\Users\HP NEW\Downloads\enlist\env\Lib\site-packages\django\db\backends\utils.py", line 92, in _execute_with_wrappers
    return executor(sql, params, many, context)
           ^^^^^^^^^^^^^^^^^^^^^^^^^^^^^^^^^^^^
  File "C:\Users\HP NEW\Downloads\enlist\env\Lib\site-packages\django\db\backends\utils.py", line 100, in _execute
    with self.db.wrap_database_errors:
  File "C:\Users\HP NEW\Downloads\enlist\env\Lib\site-packages\django\db\utils.py", line 91, in __exit__
    raise dj_exc_value.with_traceback(traceback) from exc_value
  File "C:\Users\HP NEW\Downloads\enlist\env\Lib\site-packages\django\db\backends\utils.py", line 105, in _execute
    return self.cursor.execute(sql, params)
           ^^^^^^^^^^^^^^^^^^^^^^^^^^^^^^^^
django.db.utils.IntegrityError: insert or update on table "analytics_storevisitor" violates foreign key constraint "analytics_storevisit_store_id_bb8f47ea_fk_stores_st"
DETAIL:  Key (store_id)=(1) is not present in table "stores_storeuserprofile".

"GET /api/analytics/statistics/1/ HTTP/1.1" 500 165463
Internal Server Error: /api/analytics/statistics/10/
Traceback (most recent call last):
  File "C:\Users\HP NEW\Downloads\enlist\env\Lib\site-packages\django\core\handlers\exception.py", line 55, in inner
    response = get_response(request)
               ^^^^^^^^^^^^^^^^^^^^^
  File "C:\Users\HP NEW\Downloads\enlist\env\Lib\site-packages\django\core\handlers\base.py", line 197, in _get_response
    response = wrapped_callback(request, *callback_args, **callback_kwargs)
               ^^^^^^^^^^^^^^^^^^^^^^^^^^^^^^^^^^^^^^^^^^^^^^^^^^^^^^^^^^^^
  File "C:\Users\HP NEW\Downloads\enlist\env\Lib\site-packages\django\views\decorators\csrf.py", line 65, in _view_wrapper
    return view_func(request, *args, **kwargs)
           ^^^^^^^^^^^^^^^^^^^^^^^^^^^^^^^^^^^
  File "C:\Users\HP NEW\Downloads\enlist\env\Lib\site-packages\django\views\generic\base.py", line 104, in view
    return self.dispatch(request, *args, **kwargs)
           ^^^^^^^^^^^^^^^^^^^^^^^^^^^^^^^^^^^^^^^
  File "C:\Users\HP NEW\Downloads\enlist\env\Lib\site-packages\rest_framework\views.py", line 509, in dispatch
    response = self.handle_exception(exc)
               ^^^^^^^^^^^^^^^^^^^^^^^^^^
  File "C:\Users\HP NEW\Downloads\enlist\env\Lib\site-packages\rest_framework\views.py", line 469, in handle_exception
    self.raise_uncaught_exception(exc)
  File "C:\Users\HP NEW\Downloads\enlist\env\Lib\site-packages\rest_framework\views.py", line 480, in raise_uncaught_exception
    raise exc
  File "C:\Users\HP NEW\Downloads\enlist\env\Lib\site-packages\rest_framework\views.py", line 506, in dispatch
    response = handler(request, *args, **kwargs)
               ^^^^^^^^^^^^^^^^^^^^^^^^^^^^^^^^^
  File "C:\Users\HP NEW\Downloads\enlist\analytics\views.py", line 15, in get
    revenue = StoreRevenue.objects.filter(store_id=store_id, revenue_date=today).aggregate(total_revenue=Sum('revenue'))['total_revenue'] or 0
                                                                                                         ^^^
NameError: name 'Sum' is not defined. Did you mean: 'sum'?
"GET /api/analytics/statistics/10/ HTTP/1.1" 500 98447
Internal Server Error: /api/authent/register/
"POST /api/authent/register/ HTTP/1.1" 500 60
Internal Server Error: /api/authent/register/
"POST /api/authent/register/ HTTP/1.1" 500 60
